Workbook

Sheet Material Deflection
A1: Material (rods) | B1: Modulus (GPa) | C1: Density (grams/cm^3) | D1: Thickness | E1: OD (inches) | F1: I (in^4) | G1: Pressure (Psi) | H1: Displacement (inches) | I1: Weight(per member) | J1: Total W of Chassis (lbs) | K1: Total Weight | L1: Difference in weight(lbs) | M1: Reduction | N1: Weight with Driver (lbs)
A2: Chrome Moly (4130) | B2: 210 | C2: 7.85 | D2: 0.03 | E2: 0.75 | F2: =3.14*(E2^4-(E2-D2)^4)/4 -> 0.037419137 | G2: =B2*145037.738 -> 30457925 | H2: =B$16^(2)*B$17/(48*G2*F2) -> 0.026322503 | I2: =0.0361*C2*((E2^2*3.14)-((E2-D2)^2*3.14))*B$16 -> 2.3544873 | J2: =I2/B$16*$B$18*12 -> 37.671796 | K2: =J2+$B$14 -> 84.671796 | L2: =$K$6-K2 -> 48.210104 | M2: =L2/$K$6 -> 0.36280414 | N2: =K2+$B$22 -> 194.9218
A3: Aluminum (6061) | B3: 69 | C3: 2.7 | D3: 0.1 | E3: 0.75 | F3: =3.14*(E3^4-(E3-D3)^4)/4 -> 0.1082515 | G3: =B3*145037.738 -> 10007604 | H3: =B$16^(2)*B$17/(48*G3*F3) -> 0.027692185 | I3: =0.0361*C3*((E3^2*3.14)-((E3-D3)^2*3.14))*B$16 -> 2.5708687 | J3: =I3/B$16*$B$18*12 -> 41.1339 | K3: =J3+$B$14 -> 88.1339 | L3: =$K$6-K3 -> 44.748 | M3: =L3/$K$6 -> 0.33675016 | N3: =K3+$B$22 -> 198.3839
A4: Wrapped CF | B4: 260 | C4: 0.388289 | D4: 0.2 | E4: 0.625 | F4: =3.14*(E4^4-(E4-D4)^4)/4 -> 0.094170562 | G4: =B4*145037.738 -> 37709812 | H4: =B$16^(2)*B$17/(48*G4*F4) -> 0.0084479576 | I4: =0.0361*C4*((E4^2*3.14)-((E4-D4)^2*3.14))*B$16 -> 0.5545778 | J4: =I4/B$16*$B$18*12 -> 8.8732448 | K4: =J4+$B$14 -> 55.873245 | L4: =$K$6-K4 -> 77.008655 | M4: =L4/$K$6 -> 0.57952705 | N4: =K4+$B$22 -> 166.12324
A5: S. Steel (304) | B5: 193 | C5: 7.93 | D5: 0.03 | E5: 0.75 | F5: =3.14*(E5^4-(E5-D5)^4)/4 -> 0.037419137 | G5: =B5*145037.738 -> 27992283 | H5: =B$16^(2)*B$17/(48*G5*F5) -> 0.028641065 | I5: =0.0361*C5*((E5^2*3.14)-((E5-D5)^2*3.14))*B$16 -> 2.378482 | J5: =I5/B$16*$B$18*12 -> 38.055713 | K5: =J5+$B$14 -> 85.055713 | L5: =$K$6-K5 -> 47.826187 | M5: =L5/$K$6 -> 0.35991499 | N5: =K5+$B$22 -> 195.30571
A6: CURRENT (Square Aluminum) | B6: 193 | C6: 7.93 | D6: =1/8 -> 0.125 | E6: 0.75 | F6: =E6^3*D6*4/6 -> 0.03515625 | G6: =B6*145037.738 -> 27992283 | H6: =B$16^(2)*B$17/(48*G6*F6) -> 0.030484592 | I6: =0.0361*(E6^2-(E6-2*D6)^2)*B16*C6 -> 5.3676188 | J6: =I6/B$16*$B$18*12 -> 85.8819 | K6: =J6+$B$14 -> 132.8819 | N6: =K6+$B$22 -> 243.1319
A8: Current Total (lbs) | B8: 131.9
A9: Fuel Cell | B9: 7.5
A10: Tires | B10: 7 | L10: Chrome Moly (4130) | M10: 194.9218
A11: Electronics | B11: 2.5 | L11: Aluminum (6061) | M11: 198.3839
A12: Suspension | B12: 25 | L12: Wrapped CF | M12: 166.12324
A13: Safety+Etc | B13: 5 | L13: S. Steel (304) | M13: 195.30571
A14: Rest of Vehicle (lbs) | B14: =SUM(B9:B13) -> 47 | L14: CURRENT (Square Aluminum) | M14: 243.1319
A16: Member Length (in) | B16: 60
A17: Load (lbs) | B17: 400
A18: Estimate Chassis Tubing (ft) | B18: 80
A21: Estimated Length
A22: Min Weight (Driver) | B22: 110.25
A23: Max Weight (Car) | B23: 308.7
A24: NO MIN WEIGHT
A26: Suspension Weight Calculations | B26: Chrome Moly | C26: Weight (lbs)
A27: Conservative Amt of Material (ft) | B27: 20 | C27: =0.0361*$C$2*(($E$2^2*3.14)-(($E$2-$D$2)^2*3.14))*($B27*12) -> 9.4179491
A28: Aggressive Amt of Material (ft) | B28: 15 | C28: =0.0361*$C$2*(($E$2^2*3.14)-(($E$2-$D$2)^2*3.14))*($B28*12) -> 7.0634618
A31: Component of the Current Vehicle | B31: Estimated Weight (lbs) | C31: Percentage of Total Weight | G31: Test Trial | H31: Max Velocity (m/s) | I31: Max Acceleration (m/s^2) | J31: Power Exerted
A32: Fuel Cell | B32: 7.2 | C32: =B32/$B$39 -> 0.054586808 | G32: 1 | H32: 6.25 | I32: 1.28 | J32: =((I32)*($N$6*0.453)+($N$6*0.453)*(0.5))*(H32/3) -> 408.4312
A33: Tires | B33: 6.8 | C33: =B33/$B$39 -> 0.051554208 | G33: 2 | H33: 6.62 | I33: 4.04 | J33: =((I33)*($N$6*0.453)+($N$6*0.453)*(0.5))*(H33/3) -> 1103.3994
A34: Electronics | B34: 1.5 | C34: =B34/$B$39 -> 0.011372252 | G34: 3 | H34: 6.75 | I34: 3 | J34: =((I34)*($N$6*0.453)+($N$6*0.453)*(0.5))*(H34/3) -> 867.34266
A35: Suspension | B35: 25.2 | C35: =B35/$B$39 -> 0.19105383 | G35: 5 | H35: 6.5 | I35: 6.2 | J35: =((I35)*($N$6*0.453)+($N$6*0.453)*(0.5))*(H35/3) -> 1598.8475
A36: Safety+Etc | B36: 2.3 | C36: =B36/$B$39 -> 0.017437453 | G36: Average | H36: =AVERAGE(H32:H35) -> 6.53 | I36: =AVERAGE(I32:I35) -> 3.63 | J36: =AVERAGE(J32:J35) -> 994.50519
A37: Non-Chassis Systems | B37: =sum(B32:B36) -> 43 | C37: =B37/$B$39 -> 0.32600455 | J37: =(1000-J36)/1000 -> 0.005494808
A38: Chassis | B38: 88.9 | C38: =B38/$B$39 -> 0.67399545 | G38: Test Trial | H38: Max Velocity (m/s) | I38: Max Acceleration (m/s^2) | J38: Estimated Power Rating (J/s)
A39: Total Vehicle Weight | B39: =sum(B37:B38) -> 131.9 | G39: 1 | H39: 9.205 | I39: 0 | J39: =((I39)*($N$6*0.453)+($N$6*0.453)*(0.5))*(H39/3) -> 168.9712
G40: 2 | H40: 10.6 | I40: 0.1 | J40: =((I40)*($N$6*0.453)+($N$6*0.453)*(0.5))*(H40/3) -> 233.49415
G41: 3 | H41: 8.9 | I41: 4.1 | J41: =((I41)*($N$6*0.453)+($N$6*0.453)*(0.5))*(H41/3) -> 1503.0268
G42: Average | H42: =AVERAGE(H38:H41) -> 9.5683333 | I42: =AVERAGE(I38:I41) -> 1.4 | J42: =AVERAGE(J38:J41) -> 635.16406
J44: =(1000-J42)/1000 -> 0.36483594

Sheet Cost Analysis
B2: Cost of Single Joint Members | C2: Aluminum | D2: Cost of Epoxy | E2: Collar Material Cost | F2: Cost of Glass Resin | G2: Cost of Welding * | I2: *Referencing Tension Tests | J2: Cost vs Tensile Strength
C3: SW
C4: LP
C5: LW
C7: 3D printed | D7: Cost of Epoxy | E7: Cost of Print Material | F7: Cost of Glass Resin
C8: SW
C9: LP
C10: LW
C11: SP
A13: *Referencing Comp Tests | B13: Cost vs Compressive Strength | J13: Cost Vs Time of Production
B22: Cost Vs Effort

Sheet Spring Calculations
C2: Control Panel (front) | I2: Control Panel (back)
C3: Total Current Weight (lbs) | D3: ='Material Deflection'!N6 -> 243.1319 | I3: Total Current Weight (lbs) | J3: =D3 -> 243.1319
C4: Total Current Carbon Weight (lbs) | D4: ='Material Deflection'!N4 -> 166.12324 | I4: Total Current Carbon Weight (lbs) | J4: =D4 -> 166.12324
C5: % weight carried by front | D5: 0.6 | I5: % weight carried by back | J5: =1-D5 -> 0.4
C6: Unsprung weight of front (lbs) | D6: =0.5*'Material Deflection'!B10+'Material Deflection'!B12*0.5 -> 16 | I6: Unsprung weight of back (lbs) | J6: =D6 -> 16
C7: Distance from chassis to spring (in) | I7: Distance from chassis to spring (in)
C8: Distnace from chassis to center of wheel (in) | I8: Distnace from chassis to center of wheel (in)
C9: Spring Angle | I9: Spring Angle
C10: Chosen Natural Frequencies (Hz) | I10: Chosen Natural Frequencies (Hz)
C12: Current | I12: Current
C13: Corner Weights (lbs) | D13: =($D$3*$D$5)/2 -> 72.93957 | I13: Corner Weight (just back wheel) (lbs) | J13: =$J$3*$J$5 -> 97.25276
C14: Individual Corner Sprung Weight (lbs) | D14: =D13/2 -> 36.469785 | I14: Individual Corner Sprung Weight (lbs) | J14: =J13 -> 97.25276
C15: Motion Ratio of Front | D15: =($D$7/$D$8)*SIN($D$9) -> #DIV/0! | I15: Motion Ratio of Back | J15: =($J$7/$J$8)*SIN($J$9) -> #DIV/0!
C16: Front Wheel Spring Rate (N/mm) | D16: {=(D14*0.454*4*pi^(2)*$D$10^(2))/1000} -> #NAME? | I16: Back Wheel Spring Rate (N/mm) | J16: {=(J14*0.454*4*pi^(2)*$J$10^(2))/1000} -> #NAME?
C17: Effective Spring Rate Needed (N/mm) | D17: =D16*D15^2 -> #NAME? | I17: Effective Spring Rate Needed (N/mm) | J17: =J16*J15^2 -> #NAME?
C19: Carbon | I19: Carbon
C20: Corner Weights (lbs) | D20: =($D$4*$D$5)/2 -> 49.836973 | I20: Corner Weight (just back wheel) (lbs) | J20: =($J$4*$J$5)/2 -> 33.224649
C21: Individual Corner Sprung Weight (lbs) | D21: =D20/2 -> 24.918487 | I21: Individual Corner Sprung Weight (lbs) | J21: =J20 -> 33.224649
C22: Motion Ratio of Front | D22: =($D$7/$D$8)*SIN($D$9) -> #DIV/0! | I22: Motion Ratio of Back | J22: =($J$7/$J$8)*SIN($J$9) -> #DIV/0!
C23: Front Wheel Spring Rate (N/mm) | D23: {=(D21*0.454*4*pi^(2)*$D$10^(2))/1000} -> #NAME? | I23: Back Wheel Spring Rate (N/mm) | J23: {=(J21*0.454*4*pi^(2)*$J$10^(2))/1000} -> #NAME?
C24: Effective Spring Rate Needed (N/mm) | D24: =D23*D22^2 -> #NAME? | I24: Effective Spring Rate Needed (N/mm) | J24: =J23*J22^2 -> #NAME?

Sheet Fuel Model (v2)
A2: MODEL 2
B3: Control Panel | E3: Fuel Efficiency Calculations | F3: CF | G3: Current
B4: % of hydrogen leaked | C4: 0 | E4: Required energy from fuel cell (kJ) | F4: =((C31/$C$5)/1000) -> 1856.3982 | G4: =((D31/$C$5)/1000) -> 2465.7467
B5: Fuel Cell Thermo-Efficiency | C5: 0.35 | E5: Hydrogen Needed (m^3) | F5: =F4/($C$13*$C$8) -> 0.18480199 | G5: =G4/($C$13*$C$8) -> 0.24546183
B6: Distance Traveled (m) | C6: 15330 | E6: Gasoline Equivalency (kJ/m^3 of gas) | F6: =($C$16*$C$12)*1000 -> 32801340 | G6: =($C$16*$C$12)*1000 -> 32801340
B7: Average Speed (kph) | C7: 30 | E7: Amount of equivalent unlead. Gas consumed (m^3) | F7: =F5*(($C$8*$C$13)/(F6)) -> 5.6595194e-05 | G7: =G5*(($C$8*$C$13)/(G6)) -> 7.5172134e-05 | K7: =F5*C8 -> 0.015479014
B8: Density of hydrogen (kg/m^3) | C8: 0.08376 | E8: Fuel Efficiency (mi/m^3) (IN GASOLINE) | F8: =($C$6*0.000621371)/F7 -> 168311.42 | G8: =($C$6*0.000621371)/G7 -> 126717.4
B9: Asphalt Kinetic Friction Coefficient | C9: 0.5 | E9: Fuel Efficiency (MPGe) | F9: =F8/264.172 -> 637.12815 | G9: =G8/264.172 -> 479.67764
B10: Estimated Drag Coefficient | C10: 0.65 | E10: Fuel Efficiency (km/m^3) (H2) | F10: =($C$6*0.001)/F5 -> 82.953653 | G10: =($C$6*0.001)/G5 -> 62.453703 | H10: 12.360621
B11: Esimtated Frontal Area (m^2) | C11: 0.5 | E11: Fuel Efficiency (mi/m^3) (of H2) | F11: =($C$6*0.000621371)/F5 -> 51.544994 | G11: =($C$6*0.000621371)/G5 -> 38.80692
B12: Density of Unlead. Gas (kg/L) | C12: 0.7646
B13: Net Caloric Value (H2) (kJ/kg) | C13: 119930 | I13: BASE | J13: 479.67764
B14: Maximum power of HFC (J/s, W) | C14: 1000 | E14: Increased Efficiency (mi/m^3) (H2) | F14: =$F$11-$G$11 -> 12.738075 | I14: 1 | J14: 637.12815 | K14: =J14-$J$13 -> 157.45052
B15: Density of air (kg/m^3) | C15: 1.294 | E15: Increased Efficiency (mpge) | F15: =F9-G9 -> 157.45052 | I15: 1+2 | J15: 697.24638 | K15: =J15-$J$13 -> 217.56874
B16: Net Caloric Value (Unlead. Gas) (kJ/kg) | C16: 42900 | I16: 1+2+3 | J16: 896.45963 | K16: =J16-$J$13 -> 416.782
B17: Total Mass of Wrapped CF (lbs) | C17: =C18*(2/3) -> 162.08793 | I17: 2 | J17: 512.99589 | K17: =J17-$J$13 -> 33.318249
B18: Total Mass of Current (lbs) | C18: ='Material Deflection'!N6 -> 243.1319 | I18: 3 | J18: 616.72839 | K18: =J18-$J$13 -> 137.05075
I19: 2+3 | J19: 659.56614 | K19: =J19-$J$13 -> 179.8885
B20: Energy Used Calculations | C20: CF | D20: Current | H20: Increased fuel efficiency | I20: 1+3 | J20: 819.16477 | K20: =J20-$J$13 -> 339.48713
B21: Mass (kg) | C21: =$C$17*0.453592 -> 73.52179 | D21: =$C$18*0.453592 -> 110.28268 | F21: Chrome Moly (4130) | G21: 194.9218 | H21: 82.688374
B22: KE at avg vel. (J) | C22: =0.5*C21*($C$7*(1000/3600))^2 -> 2552.8399 | D22: =0.5*D21*($C$7*(1000/3600))^2 -> 3829.2599 | F22: Aluminum (6061) | G22: 198.3839 | H22: 75.813724
B23: Time taken until avg kph (secs) | C23: =C22/$C$14 -> 2.5528399 | D23: =D22/$C$14 -> 3.8292599 | F23: Wrapped CF | G23: 166.12324 | H23: 147.20986
B24: Acceleration of vehicle (m/s^2) | C24: =$C$14/(C21*$C$7*(1000/3600)) -> 1.6321692 | D24: =$C$14/(D21*$C$7*(1000/3600)) -> 1.0881128 | F24: S. Steel (304) | G24: 195.30571 | H24: 81.917675
B25: Distance accelerated(m) | C25: =0.5*C24*C23^2 -> 5.3184165 | D25: =0.5*D24*D23^2 -> 7.9776248 | F25: CURRENT (Square Aluminum) | G25: 243.1319
B26: Distance at avg vel (m) | C26: =C6-$C$25 -> 15324.682 | D26: =C6-$D$25 -> 15322.022
B27: Drag Force Losses (J/s) | C27: =(0.5*$C$15*(($C$7*(1000/3600))^2)*'Fuel Model (v2)'!$C$10*'Fuel Model (v2)'!$C$11)*($C$7*(1000/3600)) -> 121.68692 | D27: =(0.5*$C$15*(($C$7*(1000/3600))^2)*'Fuel Model (v2)'!$C$10*'Fuel Model (v2)'!$C$11)*($C$7*(1000/3600)) -> 121.68692 | G27: Fuel Efficiency Increase (MPGe)
B28: Friction losses (J/s) | C28: =0.5*(($C$9*C21))*($C$7*(1000/3600))+0.5*(0.5*(($C$9*C21))*($C$7*(1000/3600))) -> 229.75559 | D28: =0.5*(($C$9*D21))*($C$7*(1000/3600))+0.5*(0.5*(($C$9*D21))*($C$7*(1000/3600))) -> 344.63339 | E28: Chassis Weight Reduction 33% | F28: (1) | G28: =K14 -> 157.45052 | H28: =G28/$J$13 -> 0.32824235
B29: Time to complete track (sec) | C29: =C23+(C26/($C$7*(1000/3600))) -> 1841.5146 | D29: =D23+(D26/($C$7*(1000/3600))) -> 1842.4719 | E29: Frontal Area Reduced by 25% | F29: (2) | G29: =K17 -> 33.318249 | H29: =G29/$J$13 -> 0.069459667
B30: Total Frictional energy lost (J) | C30: =(C28+C27)*C29 -> 647186.53 | D30: =(D28+D27)*D29 -> 859182.09 | E30: Thermal Efficiency Increased by 10% | F30: (3) | G30: =K18 -> 137.05075 | H30: =G30/$J$13 -> 0.28571429
B31: Total energy used(J) | C31: =C30+C22 -> 649739.37 | D31: =D30+D22 -> 863011.35 | F31: (1) + (2) | G31: =K15 -> 217.56874 | H31: =G31/$J$13 -> 0.45357283
F32: (2) + (3) | G32: =K19 -> 179.8885 | H32: =G32/$J$13 -> 0.37501957
F33: (1) + (3) | G33: =K20 -> 339.48713 | H33: =G33/$J$13 -> 0.70774016
F34: (1) + (2) + (3) | G34: =K16 -> 416.782 | H34: =G34/$J$13 -> 0.86887935
F36: W/o synergy | G36: Synergy increases | J36: (1) | K36: =G28 -> 157.45052
E37: (1) + (2) | F37: =G28+G29 -> 190.76876 | G37: =G31-F37 -> 26.799979 | J37: (2) | K37: =G29 -> 33.318249
E38: (1) + (3) | F38: =G28+G30 -> 294.50127 | G38: =G33-F38 -> 44.985862 | J38: (1)+(2) Synergy | K38: =G37 -> 26.799979
E39: (2) + (3) | F39: =G29+G30 -> 170.369 | G39: =G32-F39 -> 9.5194998 | J39: (3) | K39: =G30 -> 137.05075
E40: (1) + (2) + (3) | F40: =G28+G29+G30 -> 327.81952 | G40: =G34-F40 -> 88.962477 | J40: (1) + (3) Synergy | K40: =G38 -> 44.985862
J41: (2) + (3) Synergy | K41: =G39 -> 9.5194998
J42: All Synergy | K42: =G40-G38-G39-G37 -> 7.6571368

Sheet COST ANALYSIS AND EFFICIENCY AN
A1: Tension Units | F1: Density of AL (lb/in^3) | G1: 0.1 | J1: Density of Onyx (lb/in^3) | K1: 0.043 | O1: (1-5)
A2: Sizing | B2: Type | C2: Subtotal | D2: With Carbon Fiber Tube | E2: With Epoxy/Resin | F2: Total | G2: Volume of Unit (cm^3) | H2: 75% of max Tensile Load | I2: Cost/lbf | J2: V in (in^3) | K2: Volume/Cost (in^3/$) (OF 6" MEMBERS) | L2: Cost/Volume | M2: Weight of Member (OF 6" MEMBERS) | N2: Time Taken (hrs) | O2: Effort Needed | P2: Learning Curve Rating | Q2: TimexEffort Rating
A3: SP | B3: 3D prints | C3: 3.38 | D3: ='Copy of Itemized Breakdown'!$J$4 -> 4.937069 | E3: =(0.005*'Copy of Itemized Breakdown'!$E$10)+0.1*('Copy of Itemized Breakdown'!$E$9)+0.001*('Copy of Itemized Breakdown'!$E$11) -> 5.4057167 | F3: =SUM(C3:E3) -> 13.722786 | G3: 14.24 | J3: =G3*0.0610237 -> 0.86897749 | K3: =J3/F3 -> 0.063323695 | L3: =F3/J3 -> 15.791877 | M3: =$K$1*J3+'Copy of Itemized Breakdown'!M4 -> 0.056975687 | N3: 3.76 | O3: 1 | P3: 1.5 | Q3: =O3*N3+P3 -> 5.26
A4: LP | B4: 3D prints | C4: 3.89 | D4: ='Copy of Itemized Breakdown'!$J$5 -> 7.0989796 | E4: =(0.005*'Copy of Itemized Breakdown'!$E$10)+0.1*('Copy of Itemized Breakdown'!$E$9)+0.001*('Copy of Itemized Breakdown'!$E$11) -> 5.4057167 | F4: =SUM(C4:E4) -> 16.394696 | G4: 16.39 | J4: =G4*0.0610237 -> 1.0001784 | K4: =J4/F4 -> 0.06100622 | L4: =F4/J4 -> 16.391771 | M4: =$K$1*J4+'Copy of Itemized Breakdown'!M5 -> 0.11965339 | N4: 4.63 | O4: 1.5 | P4: 1.5 | Q4: =O4*N4+P4 -> 8.445
A5: SW | B5: 3D prints | C5: 3.64 | D5: ='Copy of Itemized Breakdown'!$J$2 -> 4.9655 | E5: =(0.005*'Copy of Itemized Breakdown'!$E$10)+0.1*('Copy of Itemized Breakdown'!$E$9)+0.001*('Copy of Itemized Breakdown'!$E$11) -> 5.4057167 | F5: =SUM(C5:E5) -> 14.011217 | G5: 15.31 | H5: 167.175 | I5: =F5/H5 -> 0.083811674 | J5: =G5*0.0610237 -> 0.93427285 | K5: =J5/F5 -> 0.066680351 | L5: =F5/J5 -> 14.996922 | M5: =$K$1*J5+'Copy of Itemized Breakdown'!M2 -> 0.067375732 | N5: 3.92 | O5: 1 | P5: 1.5 | Q5: =O5*N5+P5 -> 5.42
A6: LW | B6: 3D prints | C6: 4.16 | D6: ='Copy of Itemized Breakdown'!$J$3 -> 7.3335 | E6: =(0.005*'Copy of Itemized Breakdown'!$E$10)+0.1*('Copy of Itemized Breakdown'!$E$9)+0.001*('Copy of Itemized Breakdown'!$E$11) -> 5.4057167 | F6: =SUM(C6:E6) -> 16.899217 | G6: 17.51 | H6: 96.79 | I6: =F6/H6 -> 0.17459672 | J6: =G6*0.0610237 -> 1.068525 | K6: =J6/F6 -> 0.063229261 | L6: =F6/J6 -> 15.815462 | M6: =$K$1*J6+'Copy of Itemized Breakdown'!M3 -> 0.10422857 | N6: 4.8 | O6: 1.5 | P6: 1.5 | Q6: =O6*N6+P6 -> 8.7
A7: SP | B7: AL | C7: ='Copy of Itemized Breakdown'!$L$6 -> 1.2118056 | D7: ='Copy of Itemized Breakdown'!$J$4 -> 4.937069 | E7: =(0.005*'Copy of Itemized Breakdown'!$E$10)+0.1*('Copy of Itemized Breakdown'!$E$9)+0.001*('Copy of Itemized Breakdown'!$E$11) -> 5.4057167 | F7: =SUM(C7:E7) -> 11.554591 | J7: ='Copy of Itemized Breakdown'!$K$6 -> 3.5908333 | K7: =J7/F7 -> 0.31077113 | L7: =F7/J7 -> 3.2178021 | M7: =$G$1*J7+'Copy of Itemized Breakdown'!M4 -> 0.37869299 | N7: 2 | O7: 4 | P7: 3 | Q7: =O7*N7+P7 -> 11
A8: LP | B8: AL | C8: ='Copy of Itemized Breakdown'!$L$6 -> 1.2118056 | D8: ='Copy of Itemized Breakdown'!$J$5 -> 7.0989796 | E8: =(0.005*'Copy of Itemized Breakdown'!$E$10)+0.1*('Copy of Itemized Breakdown'!$E$9)+0.001*('Copy of Itemized Breakdown'!$E$11) -> 5.4057167 | F8: =SUM(C8:E8) -> 13.716502 | H8: 316.75 | I8: =F8/H8 -> 0.043303873 | J8: ='Copy of Itemized Breakdown'!$K$6 -> 3.5908333 | K8: =J8/F8 -> 0.26178929 | L8: =F8/J8 -> 3.8198659 | M8: =$G$1*J8+'Copy of Itemized Breakdown'!M5 -> 0.43572905 | N8: 2 | O8: 3 | P8: 3 | Q8: =O8*N8+P8 -> 9
A9: SW | B9: AL | C9: ='Copy of Itemized Breakdown'!$L$6 -> 1.2118056 | D9: ='Copy of Itemized Breakdown'!$J$2 -> 4.9655 | E9: =(0.005*'Copy of Itemized Breakdown'!$E$10)+0.1*('Copy of Itemized Breakdown'!$E$9)+0.001*('Copy of Itemized Breakdown'!$E$11) -> 5.4057167 | F9: =SUM(C9:E9) -> 11.583022 | H9: 420.87 | I9: =F9/H9 -> 0.027521615 | J9: ='Copy of Itemized Breakdown'!$K$6 -> 3.5908333 | K9: =J9/F9 -> 0.31000833 | L9: =F9/J9 -> 3.2257198 | M9: =$G$1*J9+'Copy of Itemized Breakdown'!M2 -> 0.38628533 | N9: 2 | O9: 4 | P9: 3 | Q9: =O9*N9+P9 -> 11
A10: LW | B10: AL | C10: ='Copy of Itemized Breakdown'!$L$6 -> 1.2118056 | D10: ='Copy of Itemized Breakdown'!$J$3 -> 7.3335 | E10: =(0.005*'Copy of Itemized Breakdown'!$E$10)+0.1*('Copy of Itemized Breakdown'!$E$9)+0.001*('Copy of Itemized Breakdown'!$E$11) -> 5.4057167 | F10: =SUM(C10:E10) -> 13.951022 | H10: 447.27 | I10: =F10/H10 -> 0.0311915 | J10: ='Copy of Itemized Breakdown'!$K$6 -> 3.5908333 | K10: =J10/F10 -> 0.25738855 | L10: =F10/J10 -> 3.8851768 | M10: =$G$1*J10+'Copy of Itemized Breakdown'!M3 -> 0.41736533 | N10: 2 | O10: 3 | P10: 3 | Q10: =O10*N10+P10 -> 9
G11: SW 3D print with hardware | H11: 294.75 | I11: =F5/H11 -> 0.047535934
A12: Compression
A13: Sizing | B13: Type | C13: Subtotal | D13: With Carbon Fiber Tube | E13: With Epoxy/Resin | F13: Total | G13: Volume of Unit (cm^3) | H13: 75% of max compressive load | I13: Cost/lbf | J13: V in (in^3) | K13: Volume/Cost (in^3/$) (OF 6" MEMBERS) | L13: Cost/Volume | M13: Weight of Member (OF 6" MEMBERS) | N13: Time Taken (hrs) | O13: Effort Needed | P13: Learning Curve Rating | Q13: TimexEffort Rating
A14: SP | B14: 3D prints | C14: 5.7 | D14: ='Copy of Itemized Breakdown'!$J$4 -> 4.937069 | E14: =(0.005*'Copy of Itemized Breakdown'!$E$10)+0.1*('Copy of Itemized Breakdown'!$E$9)+0.001*('Copy of Itemized Breakdown'!$E$11) -> 5.4057167 | F14: =SUM(C14:E14) -> 16.042786 | G14: 23.99 | I14: =F14/H14 -> #DIV/0! | J14: =G14*0.0610237 -> 1.4639586 | K14: =J14/F14 -> 0.091253389 | L14: =F14/J14 -> 10.958497 | M14: =$K$1*J14+'Copy of Itemized Breakdown'!M4 -> 0.082559873 | N14: 5.85 | O14: 1 | P14: 1.5 | Q14: =O14*N14+P14 -> 7.35
A15: LP | B15: 3D prints | C15: 7.96 | D15: ='Copy of Itemized Breakdown'!$J$5 -> 7.0989796 | E15: =(0.005*'Copy of Itemized Breakdown'!$E$10)+0.1*('Copy of Itemized Breakdown'!$E$9)+0.001*('Copy of Itemized Breakdown'!$E$11) -> 5.4057167 | F15: =SUM(C15:E15) -> 20.464696 | G15: 33.52 | H15: 73.5 | I15: =F15/H15 -> 0.27843124 | J15: =G15*0.0610237 -> 2.0455144 | K15: =J15/F15 -> 0.099953324 | L15: =F15/J15 -> 10.00467 | M15: =$K$1*J15+'Copy of Itemized Breakdown'!M5 -> 0.16460283 | N15: 7.85 | O15: 1 | P15: 1.5 | Q15: =O15*N15+P15 -> 9.35
A16: SW | B16: 3D prints | C16: 3.76 | D16: ='Copy of Itemized Breakdown'!$J$2 -> 4.9655 | E16: =(0.005*'Copy of Itemized Breakdown'!$E$10)+0.1*('Copy of Itemized Breakdown'!$E$9)+0.001*('Copy of Itemized Breakdown'!$E$11) -> 5.4057167 | F16: =SUM(C16:E16) -> 14.131217 | G16: 15.84 | I16: =F16/H16 -> #DIV/0! | J16: =G16*0.0610237 -> 0.96661541 | K16: =J16/F16 -> 0.068402844 | L16: =F16/J16 -> 14.619275 | M16: =$K$1*J16+'Copy of Itemized Breakdown'!M2 -> 0.068766463 | N16: 5.47 | O16: 1 | P16: 1.5 | Q16: =O16*N16+P16 -> 6.97
A17: LW | B17: 3D prints | C17: 9.01 | D17: ='Copy of Itemized Breakdown'!$J$3 -> 7.3335 | E17: =(0.005*'Copy of Itemized Breakdown'!$E$10)+0.1*('Copy of Itemized Breakdown'!$E$9)+0.001*('Copy of Itemized Breakdown'!$E$11) -> 5.4057167 | F17: =SUM(C17:E17) -> 21.749217 | G17: 37.93 | H17: 113.25 | I17: =F17/H17 -> 0.19204606 | J17: =G17*0.0610237 -> 2.3146289 | K17: =J17/F17 -> 0.10642355 | L17: =F17/J17 -> 9.3964161 | M17: =$K$1*J17+'Copy of Itemized Breakdown'!M3 -> 0.15781104 | N17: 9.23 | O17: 1 | P17: 1.5 | Q17: =O17*N17+P17 -> 10.73
A18: SP | B18: AL | C18: ='Copy of Itemized Breakdown'!$L$6 -> 1.2118056 | D18: ='Copy of Itemized Breakdown'!$J$4 -> 4.937069 | E18: =(0.005*'Copy of Itemized Breakdown'!$E$10)+0.1*('Copy of Itemized Breakdown'!$E$9)+0.001*('Copy of Itemized Breakdown'!$E$11) -> 5.4057167 | F18: =SUM(C18:E18) -> 11.554591 | I18: =F18/H18 -> #DIV/0! | J18: ='Copy of Itemized Breakdown'!$K$6 -> 3.5908333 | K18: =J18/F18 -> 0.31077113 | L18: =F18/J18 -> 3.2178021 | M18: =$G$1*J18+'Copy of Itemized Breakdown'!M4 -> 0.37869299 | N18: 2 | O18: 4 | P18: 3 | Q18: =O18*N18+P18 -> 11
A19: LP | B19: AL | C19: ='Copy of Itemized Breakdown'!$L$6 -> 1.2118056 | D19: ='Copy of Itemized Breakdown'!$J$5 -> 7.0989796 | E19: =(0.005*'Copy of Itemized Breakdown'!$E$10)+0.1*('Copy of Itemized Breakdown'!$E$9)+0.001*('Copy of Itemized Breakdown'!$E$11) -> 5.4057167 | F19: =SUM(C19:E19) -> 13.716502 | H19: 67.5 | I19: =F19/H19 -> 0.20320743 | J19: ='Copy of Itemized Breakdown'!$K$6 -> 3.5908333 | K19: =J19/F19 -> 0.26178929 | L19: =F19/J19 -> 3.8198659 | M19: =$G$1*J19+'Copy of Itemized Breakdown'!M5 -> 0.43572905 | N19: 2 | O19: 3 | P19: 3 | Q19: =O19*N19+P19 -> 9
A20: SW | B20: AL | C20: ='Copy of Itemized Breakdown'!$L$6 -> 1.2118056 | D20: ='Copy of Itemized Breakdown'!$J$2 -> 4.9655 | E20: =(0.005*'Copy of Itemized Breakdown'!$E$10)+0.1*('Copy of Itemized Breakdown'!$E$9)+0.001*('Copy of Itemized Breakdown'!$E$11) -> 5.4057167 | F20: =SUM(C20:E20) -> 11.583022 | H20: 256.5 | I20: =F20/H20 -> 0.045157981 | J20: ='Copy of Itemized Breakdown'!$K$6 -> 3.5908333 | K20: =J20/F20 -> 0.31000833 | L20: =F20/J20 -> 3.2257198 | M20: =$G$1*J20+'Copy of Itemized Breakdown'!M2 -> 0.38628533 | N20: 2 | O20: 4 | P20: 3 | Q20: =O20*N20+P20 -> 11
A21: LW | B21: AL | C21: ='Copy of Itemized Breakdown'!$L$6 -> 1.2118056 | D21: ='Copy of Itemized Breakdown'!$J$3 -> 7.3335 | E21: =(0.005*'Copy of Itemized Breakdown'!$E$10)+0.1*('Copy of Itemized Breakdown'!$E$9)+0.001*('Copy of Itemized Breakdown'!$E$11) -> 5.4057167 | F21: =SUM(C21:E21) -> 13.951022 | H21: 1173 | I21: =F21/H21 -> 0.011893455 | J21: ='Copy of Itemized Breakdown'!$K$6 -> 3.5908333 | K21: =J21/F21 -> 0.25738855 | L21: =F21/J21 -> 3.8851768 | M21: =$G$1*J21+'Copy of Itemized Breakdown'!M3 -> 0.41736533 | N21: 2 | O21: 3 | P21: 3 | Q21: =O21*N21+P21 -> 9
E22: LW MEMBER | F22: =2*'Copy of Itemized Breakdown'!J3 -> 14.667 | H22: 3863 | I22: =F22/H22 -> 0.0037967901
A23: Material (rods) | B23: Modulus (GPa) | C23: Density (grams/cm^3) | D23: Thickness | E23: OD (inches) | F23: I (in^4) | G23: Pressure (Psi) | H23: Displacement (inches) | I23: Weight(per member) | J23: Total W of Chassis (lbs) | K23: Total Weight | L23: Reduction | M23: Weight with Driver (lbs)
A24: Wrapped CF | B24: 260 | C24: 0.388289 | D24: 0.2 | E24: 0.625 | F24: 0.094170562 | G24: 37709812 | H24: 0.0084479576 | I24: 0.5545778 | J24: 8.8732448 | K24: 55.873245 | L24: 0.58 | M24: 166.12324
A25: CURRENT (Square Aluminum) | B25: 193 | C25: 7.93 | D25: 0.125 | E25: 0.75 | F25: 0.03515625 | G25: 27992283 | H25: 0.030484592 | I25: 5.3676188 | J25: 85.8819 | K25: 132.8819 | N25: 243.1319
A26: Weight of Joints
A28: Sizing | B28: Type | C28: Weight of each member | D28: Total W of Chassis | E28: Total Weight | F28: Difference in Weight | G28: Reduction % | H28: Weight with Driver | I28: Cost/(lb saved) | J28: Projected Fuel Efficiency (mi/m^3) | K28: Increased Fuel Effiency | L28: Fuel Efficiency Gained/Lb Saved | M28: Cost/Efficiency Gained
A29: SP | B29: 3D prints | C29: 0.082559873 | D29: =(C29/6)*80*12 -> 13.20958 | E29: =D29+47 -> 60.20958 | F29: =$K$25-E29 -> 72.67232 | G29: =F29/$N$25 -> 0.2989008 | H29: ='Material Deflection'!$B$22+E29 -> 170.45958 | I29: =((F14/6)*80*12)/F29 -> 35.320817 | J29: 76.230609 | K29: 17.844355 | L29: =K29/F29 -> 0.24554541 | M29: =((F14/6)*80*12)/K29 -> 143.84637
A30: LP | B30: 3D prints | C30: 0.16460283 | D30: =(C30/6)*80*12 -> 26.336454 | E30: =D30+47 -> 73.336454 | F30: =$K$25-E30 -> 59.545446 | G30: =F30/$K$25 -> 0.44810803 | H30: ='Material Deflection'!$B$22+E30 -> 183.58645 | I30: =((F15/6)*80*12)/F30 -> 54.989115 | J30: 72.245283 | K30: 13.859029 | L30: =K30/F30 -> 0.23274709 | M30: =((F15/6)*80*12)/K30 -> 236.26124
A31: SW | B31: 3D prints | C31: 0.068766463 | D31: =(C31/6)*80*12 -> 11.002634 | E31: =D31+47 -> 58.002634 | F31: =$K$25-E31 -> 74.879266 | G31: =F31/$K$25 -> 0.56350237 | H31: ='Material Deflection'!$B$22+E31 -> 168.25263 | I31: =((F16/6)*80*12)/F31 -> 30.195203 | J31: 76.944078 | K31: 18.557824 | L31: =K31/F31 -> 0.24783662 | M31: =((F16/6)*80*12)/K31 -> 121.83512
A32: LW | B32: 3D prints | C32: 0.15781104 | D32: =(C32/6)*80*12 -> 25.249767 | E32: =D32+47 -> 72.249767 | F32: =$K$25-E32 -> 60.632133 | G32: =F32/$K$25 -> 0.45628587 | H32: ='Material Deflection'!$B$22+E32 -> 182.49977 | I32: =((F17/6)*80*12)/F32 -> 57.393242 | J32: 72.559361 | K32: 14.173107 | L32: =K32/F32 -> 0.23375571 | M32: =((F17/6)*80*12)/K32 -> 245.52659
A33: SP | B33: AL | C33: 0.37869299 | D33: =(C33/6)*80*12 -> 60.590878 | E33: =D33+47 -> 107.59088 | F33: =$K$25-E33 -> 25.291022 | G33: =F33/$K$25 -> 0.19032706 | H33: ='Material Deflection'!$B$22+E33 -> 217.84088 | I33: =((F18/6)*80*12)/F33 -> 73.098454 | J33: 63.567899 | K33: 5.181645 | L33: =K33/F33 -> 0.20488081 | M33: =((F18/6)*80*12)/K33 -> 356.78526
A34: LP | B34: AL | C34: 0.43572905 | D34: =(C34/6)*80*12 -> 69.716648 | E34: =D34+47 -> 116.71665 | F34: =$K$25-E34 -> 16.165252 | G34: =F34/$K$25 -> 0.12165127 | H34: ='Material Deflection'!$B$22+E34 -> 226.96665 | I34: =((F19/6)*80*12)/F34 -> 135.76282 | J34: 61.595829 | K34: 3.2095745 | L34: =K34/F34 -> 0.19854775 | M34: =((F19/6)*80*12)/K34 -> 683.7792
A35: SW | B35: AL | C35: 0.38628533 | D35: =(C35/6)*80*12 -> 61.805653 | E35: =D35+47 -> 108.80565 | F35: =$K$25-E35 -> 24.076247 | G35: =F35/$K$25 -> 0.1811853 | H35: ='Material Deflection'!$B$22+E35 -> 219.05565 | I35: =((F20/6)*80*12)/F35 -> 76.975601 | J35: 63.298159 | K35: 4.9119052 | L35: =K35/F35 -> 0.20401457 | M35: =((F20/6)*80*12)/K35 -> 377.30442
A36: LW | B36: AL | C36: 0.41736533 | D36: =(C36/6)*80*12 -> 66.778453 | E36: =D36+47 -> 113.77845 | F36: =$K$25-E36 -> 19.103447 | G36: =F36/$K$25 -> 0.14376259 | H36: ='Material Deflection'!$B$22+E36 -> 224.02845 | I36: =((F21/6)*80*12)/F36 -> 116.84612 | J36: 62.217328 | K36: 3.8310744 | L36: =K36/F36 -> 0.20054362 | M36: =((F21/6)*80*12)/K36 -> 582.64689
I38: Same Calcs in MPG | J38: PROJECTED MPG | K38: MPG GAIN | L38: MPG/Lb saved | M38: $/MPG Gain
H39: SP | I39: 3D prints | J39: =J29*12.3606212562687 -> 942.25769 | K39: =K29*12.3606212562687 -> 220.56731 | L39: =L29*12.3606212562687 -> 3.0350938 | M39: =((F14/6)*80*12)/K39 -> 11.637471
H40: LP | I40: 3D prints | J40: =J30*12.3606212562687 -> 892.99658 | K40: =K30*12.3606212562687 -> 171.30621 | L40: =L30*12.3606212562687 -> 2.8768986 | M40: =((F15/6)*80*12)/K40 -> 19.114026
H41: SW | I41: 3D prints | J41: =J31*12.3606212562687 -> 951.07661 | K41: =K31*12.3606212562687 -> 229.38624 | L41: =L31*12.3606212562687 -> 3.0634146 | M41: =((F16/6)*80*12)/K41 -> 9.8567146
H42: LW | I42: 3D prints | J42: =J32*12.3606212562687 -> 896.87878 | K42: =K32*12.3606212562687 -> 175.18841 | L42: =L32*12.3606212562687 -> 2.8893657 | M42: =((F17/6)*80*12)/K42 -> 19.863613
...

Sheet Copy of Itemized Breakdown
A1: Item | B1: Purchased from | C1: Subtotal | D1: Additional Fees | E1: Total | F1: Total Volume (in^3) | G1: Cost per in^3 | H1: Surface Area | I1: Volume of 6" | J1: Cost of 6" member | K1: Volume of 2" | L1: Cost of 2" member | M1: Weight of Each member
A2: .5" x 60" Wrapped Carbon Tube | B2: Goodwinds Composite | C2: 37.68 | D2: =47.9/4 -> 11.975 | E2: =C2+D2 -> 49.655 | F2: 19.43 | G2: =E2/F2 -> 2.5555841 | H2: =F2/60 -> 0.32383333 | I2: =H2*6 -> 1.943 | J2: =I2*G2 -> 4.9655 | M2: =I2*$M$12 -> 0.027202
A3: .750" x 60" Wrapped Carbon Tube | B3: Goodwinds Composite | C3: 61.36 | D3: =47.9/4 -> 11.975 | E3: =C3+D3 -> 73.335 | F3: 41.63 | G3: =E3/F3 -> 1.7615902 | H3: =F3/60 -> 0.69383333 | I3: =H3*6 -> 4.163 | J3: =I3*G3 -> 7.3335 | M3: =I3*$M$12 -> 0.058282
A4: .5" x 48" Pultruded Carbon Tube | B4: Goodwinds Composite | C4: 35.75 | D4: =47.9/4 -> 11.975 | E4: =C4+D4 -> 47.725 | F4: 13.54 | G4: =E4/F4 -> 3.5247415 | H4: =F4/58 -> 0.23344828 | I4: =H4*6 -> 1.4006897 | J4: =I4*G4 -> 4.937069 | M4: =I4*$M$12 -> 0.019609655
A5: .750" x 48" Pultruded Carbon Tube | B5: Goodwinds Composite | C5: 46 | D5: =47.9/4 -> 11.975 | E5: =C5+D5 -> 57.975 | F5: 44.71 | G5: =E5/F5 -> 1.2966898 | H5: =F5/49 -> 0.91244898 | I5: =H5*6 -> 5.4746939 | J5: =I5*G5 -> 7.0989796 | M5: =I5*$M$12 -> 0.076645714
A6: .750" x 24" Aluminium Rod | B6: McMaster Carr | C6: 12.28 | D6: =13.57/6 -> 2.2616667 | E6: =C6+D6 -> 14.541667 | F6: 43.09 | G6: =E6/F6 -> 0.33747196 | H6: =F6/24 -> 1.7954167 | K6: =H6*2 -> 3.5908333 | L6: =K6*G6 -> 1.2118056 | M6: =K6*0.1 -> 0.35908333
A7: .500" x 24" Aluminium Rod | B7: McMaster Carr | C7: 4.1 | D7: =13.57/6 -> 2.2616667 | E7: =C7+D7 -> 6.3616667 | F7: 19.69 | G7: =E7/F7 -> 0.32309125 | H7: =F7/24 -> 0.82041667 | K7: =H7*2 -> 1.6408333 | L7: =K7*G7 -> 0.53013889 | M7: =K7*0.1 -> 0.16408333
A8: Multipurpose 6061 Aluminum | B8: McMaster Carr | C8: 47.92 | D8: =13.57/6 -> 2.2616667 | E8: =C8+D8 -> 50.181667
A9: Toughened Epoxy | B9: McMaster Carr | C9: 49.28 | D9: =13.57/6 -> 2.2616667 | E9: =C9+D9 -> 51.541667
A10: Glass Resin FIller | B10: McMaster Carr | C10: 20.55 | D10: =13.57/6 -> 2.2616667 | E10: =C10+D10 -> 22.811667
A11: Dispensing Gun | B11: McMaster Carr | C11: 135.23 | D11: =13.57/6 -> 2.2616667 | E11: =C11+D11 -> 137.49167 | L11: Density of Pultruded CF | M11: 0.015
A12: Dispensing Gun | B12: Amazon | C12: 18.59 | D12: 1.01 | E12: =C12+D12 -> 19.6 | L12: Density of Wrapped CF | M12: 0.014
A13: Application Tips | B13: Amazon | C13: 21.79 | D13: 1.01 | E13: =C13+D13 -> 22.8

Sheet Fuel Efficiency (v1)
A2: MODEL 1 | B2: Control Panel | E2: Fuel Efficiency Calculations (total energy expended)
B3: Amount of hydrogen used (m^3) | C3: 0.001 | E3: Energy from H2 (kJ) | F3: =$C$3*$C$7*$C$9 -> 10.045337
B4: % hydrogen leaked | C4: 0 | E4: Gasoline Conversion (kJ/m^3 of gas) | F4: =$C$10*($C$8*1000) -> 32801340
B5: Fuel Cell Thermo-efficiency | C5: 0.15 | E5: Amount of equivalent unlead. Gas consumed (m^3) | F5: =F3/F4 -> 3.0624776e-07
B6: Time (min) | C6: 30 | E6: Fuel Efficiency of CF (km/m^3 of gasoline) | F6: =$C22/$F$5 -> 1175331.8
B7: Density of hydrogen (kg/m^3) | C7: 0.08376 | E7: Fuel Efficiency of Current (km/m^3 of gasoline) | F7: =$C23/$F$5 -> 971166.22
A8: IN KG/L | B8: Density of Unlead. Gas (kg/L) | C8: 0.7646 | E8: Increased Effiency (km/m^3): | F8: =F6-F7 -> 204165.61
B9: Net Caloric Value (H2) (kJ/kg) | C9: 119930
B10: Net Caloric Value (Unlead. Gas) (kJ/kg) | C10: 42900 | E10: CF in MPG | F10: =$F6*(2.35*10^(-3)) -> 2762.0298
B11: Total Mass of Wrapped CF (lbs) | C11: 166 | E11: Current in MPG | F11: =$F7*(2.35*10^(-3)) -> 2282.2406 | G11: =F11/0.00378 -> 603767.36
B12: Total Mass of Current (lbs) | C12: ='Material Deflection'!N6 -> 243.1319 | E12: Increased Effiency (in MPG): | F12: =F10-F11 -> 479.78917
B15: Distance Traveled Calculations
B16: Hydrogen Into Fuel Cell (m^3) | C16: =$C$3*(1-$C$4) -> 0.001
B17: Potential Energy into Fuel Cell (kJ) | C17: =C16*$F$3 -> 0.010045337
B18: Converted Energy to Electrical (kJ) | C18: =$C$5*C17 -> 0.0015068005
B19: Time Ran (seconds) | C19: =$C$6*60 -> 1800
B20: Weight Conversion (CF) (kg) | C20: =0.454*$C$11 -> 75.364
B21: Weight Conversion (Alum) (kg) | C21: =0.454*$C$12 -> 110.38188
B22: Distance by CF (km) | C22: =SQRT((2*$C$18*1000*$C$19^(2))/($C20))/1000 -> 0.35994274
B23: Distance by Current (km) | C23: =SQRT((2*$C$18*1000*$C$19^(2))/($C21))/1000 -> 0.29741748
